<?xml version="1.0"?>
<robot xmlns:xacro="http://wiki.ros.org/xacro" name="rover_wheel">

  <xacro:macro name="continuous_joint" params="name parent child xyz rpy">
    <joint name="${name}" type="continuous">
      <origin xyz="${xyz}" rpy="${rpy}"/>
      <parent link="${parent}"/>
      <child link="${child}"/>
      <axis xyz="0.00000 0.00000 1.00000"/>
      <limit effort="2000" velocity="100"/>
      <dynamics damping="0.05" friction="0.1"/>
    </joint>
  </xacro:macro>

  <xacro:macro name="robot_link_collision" params="name mesh scale origin_xyz origin_rpy">
    <collision name="${name}_collision">
      <origin xyz="${origin_xyz}" rpy="${origin_rpy}"/>
      <geometry>
        <mesh filename="${mesh}" scale="${scale}"/>
      </geometry>
      <surface>
        <friction>
          <ode>
            <mu>1.000000</mu>
            <mu2>1.000000</mu2>
            <fdir1>0.000000 0.000000 1.000000</fdir1>
            <slip1>0.50000</slip1>
            <slip2>0.50000</slip2>
          </ode>
        </friction>
      </surface>
    </collision>
  </xacro:macro>

  <xacro:macro name="robot_link_transmission" params="name">
    <transmission name="${name}_wheel_joint_trans">
      <type>transmission_interface/SimpleTransmission</type>
      <joint name="${name}">
        <hardwareInterface>hardware_interface/VelocityJointInterface</hardwareInterface>
      </joint>
      <actuator name="${name}wheel_joint_motor">
        <mechanicalReduction>1</mechanicalReduction>
      </actuator>
    </transmission>
  </xacro:macro>

  <xacro:macro name="robot_link_inertial" params="mass ixx ixy ixz iyy iyz izz origin_xyz origin_rpy">
    <inertial>
      <origin xyz="${origin_xyz}" rpy="${origin_rpy}"/>
      <mass value="${mass}"/>
      <inertia 
        ixx="${ixx}" ixy="${ixy}" ixz="${ixz}"
        iyy="${iyy}" iyz="${iyz}" izz="${izz}"/>
    </inertial>
  </xacro:macro>

  <xacro:macro name="robot_link_visual" params="name mesh scale material origin_xyz origin_rpy">
    <visual name="${name}_visual">
      <origin xyz="${origin_xyz}" rpy="${origin_rpy}"/>
      <material name="${material}"/>
      <geometry>
        <mesh filename="${mesh}" scale="${scale}"/>
      </geometry>
    </visual>
  </xacro:macro>

  <xacro:continuous_joint name="back_left_wheel_joint" parent="wheel_center.1_link" child="back_left_wheel_link" xyz="0.00000 -0.00000 -0.22269" rpy="3.14159 0.00000 0.00000"/>
  <xacro:continuous_joint name="back_right_wheel_joint" parent="wheel_center.2_link" child="back_right_wheel_link" xyz="0.00000 0.00000 -0.17236" rpy="-3.14159 0.00000 0.00000"/>
  <xacro:continuous_joint name="front_left_wheel_joint" parent="wheel_center.3_link" child="front_left_wheel_link" xyz="0.00000 -0.00000 -0.22269" rpy="3.14159 0.00000 0.00000"/>
  <xacro:continuous_joint name="front_right_wheel_joint" parent="wheel_center.4_link" child="front_right_wheel_link" xyz="0.02853 0.00000 -0.17236" rpy="-3.14159 0.00000 0.00000"/>

  <link name="back_left_wheel_link">
    <xacro:robot_link_collision name="back_left_wheel" mesh="package://rover_description/meshes/dae/Cylinder.038.dae" scale="0.10000 0.10000 0.10000" origin_xyz="-0.00000 -0.00000 -0.00000" origin_rpy="0.00000 0.00000 0.00000"/>
    <xacro:robot_link_inertial mass="10.00000" ixx="1.39644" ixy="-0.00000" ixz="-0.00000" iyy="2.63328" iyz="-0.00000" izz="1.39644" origin_xyz="-0.00000 -0.00000 -0.00000" origin_rpy="0.00000 0.00000 0.00000"/>
    <xacro:robot_link_visual name="back_left_wheel" mesh="package://rover_description/meshes/dae/Cylinder.038.dae" scale="0.10000 0.10000 0.10000" material="Material.004" origin_xyz="-0.00000 -0.00000 -0.00000" origin_rpy="0.00000 0.00000 0.00000"/>
    <xacro:robot_link_transmission name="back_left_wheel_joint"/>
  </link>

  <link name="back_right_wheel_link">
    <xacro:robot_link_collision name="back_right_wheel" mesh="package://rover_description/meshes/dae/Cylinder.037.dae" scale="0.10000 0.10000 0.10000" origin_xyz="-0.00000 0.00000 -0.00000" origin_rpy="3.14159 0.00000 0.00000"/>
    <xacro:robot_link_inertial mass="10.00000" ixx="1.39644" ixy="-0.00000" ixz="-0.00000" iyy="2.63328" iyz="-0.00000" izz="1.39644" origin_xyz="-0.00000 0.00000 0.00000" origin_rpy="0.00000 0.00000 0.00000"/>
    <xacro:robot_link_visual name="back_right_wheel" mesh="package://rover_description/meshes/dae/Cylinder.037.dae" scale="0.10000 0.10000 0.10000" material="Material.001" origin_xyz="-0.00000 0.00000 -0.00000" origin_rpy="3.14159 0.00000 0.00000"/>
    <xacro:robot_link_transmission name="back_right_wheel_joint"/>
  </link>

  <link name="front_left_wheel_link">
    <xacro:robot_link_collision name="front_left_wheel" mesh="package://rover_description/meshes/dae/Cylinder.036.dae" scale="0.10000 0.10000 0.10000" origin_xyz="-0.00000 0.00000 0.00000" origin_rpy="0.00000 0.00000 0.00000"/>
    <xacro:robot_link_inertial mass="10.00000" ixx="0.70986" ixy="0.00000" ixz="0.00000" iyy="1.17034" iyz="-0.00000" izz="0.70986" origin_xyz="-0.00000 0.00000 0.00000" origin_rpy="0.00000 0.00000 0.00000"/>
    <xacro:robot_link_visual name="front_left_wheel" mesh="package://rover_description/meshes/dae/Cylinder.036.dae" scale="0.10000 0.10000 0.10000" material="Material.003" origin_xyz="-0.00000 0.00000 -0.00000" origin_rpy="0.00000 0.00000 0.00000"/>
    <xacro:robot_link_transmission name="front_left_wheel_joint"/>
  </link>

  <link name="front_right_wheel_link">
    <xacro:robot_link_collision name="front_right_wheel" mesh="package://rover_description/meshes/dae/Cylinder.003.dae" scale="0.10000 0.10000 0.10000" origin_xyz="-0.00000 0.00000 -0.00000" origin_rpy="3.14159 0.00000 0.00000"/>
    <xacro:robot_link_inertial mass="10.00000" ixx="0.70986" ixy="0.00000" ixz="0.00000" iyy="1.17034" iyz="-0.00000" izz="0.70986" origin_xyz="-0.00000 0.00000 0.00000" origin_rpy="0.00000 0.00000 0.00000"/>
    <xacro:robot_link_visual name="front_right_wheel" mesh="package://rover_description/meshes/dae/Cylinder.003.dae" scale="0.10000 0.10000 0.10000" material="Material.002" origin_xyz="-0.00000 0.00000 -0.00000" origin_rpy="3.14159 0.00000 0.00000"/>
    <xacro:robot_link_transmission name="front_right_wheel_joint"/>
  </link>

</robot>